Workbook

Sheet Read Me
A1: DEMO DATA: based on real shipments, with each bag's amounts randomly scaled (up to ±15%) and identifying details removed for the founder's privacy.
A3: How to use this tracker
A4: One row per bag, including bags that haven't sold yet. Fill it in on the Bags tab; the Summary tab updates itself.
A6: Colour key
A7: Yellow column header = you fill this in.
A8: Grey column header / grey cells = calculated automatically. Don't type over these.
A9: Hover over a column header to see what goes in it.
A11: Getting started
A12: 1. Look at the example row (row 3, grey italic) to see the format, then overwrite or delete it.
A13: 2. Start with sold bags from Vinted and Vestiaire Collective (sold-items history and sale/payout emails).
A14: 3. Add the purchase side from your own records: supplier messages, bank/PayPal transfers, invoices, shipping receipts.
A15: 4. Add bags you still have (listed or not) so we can see what's slow to sell.
... A24: • Bags with status other than 'Sold' don't count towards profit; their cost shows as unsold stock.

Sheet Bags
A1: ITEM | K1: SOURCING | Y1: LISTING | AD1: SALE | AH1: RESULTS | AO1: NOTES
A2: Bag ID | B2: Brand | C2: Model / style | D2: Size | E2: Colour | F2: Material | G2: Year / date code | H2: Condition | I2: Box / dust bag / receipt | J2: Authentication | K2: Supplier / source | L2: Sourcing type | M2: Lot ID | N2: Lot total price (£) | O2: Purchase date | P2: Purchase price (original currency) | Q2: Purchase currency | R2: FX rate to GBP | S2: Purchase price (£) | T2: Shipping to London (£) | U2: Import duty & VAT (£) | V2: Authentication cost (£) | W2: Other costs (£) | X2: Total landed cost (£) | Y2: Channel | Z2: Date listed | AA2: First list price (£) | AB2: No. of price cuts | AC2: Status | AD2: Date sold | AE2: Sale price (£) | AF2: Net payout received (£) | AG2: Seller-paid shipping / packaging (£) | AH2: Fees & deductions (£) | AI2: Profit (£) | AJ2: Margin % | AK2: ROI % | AL2: Days to sell | AM2: Discount vs first list % | AN2: Days in stock (unsold) | AO2: Data confidence | AP2: Notes
A3: DEMO-001 | B3: Fendi | C3: Baguette | E3: Pink | F3: Leather | H3: Satisfactory | K3: Supplier A | L3: Clearance lot | M3: LOT-A | N3: 336 | O3: 46215 | P3: 11 | Q3: GBP | R3: 1 | S3: =IF(OR(P3="",R3=""),"",P3*R3) -> 11 | T3: 12 | U3: 0 | V3: 0 | W3: 0 | X3: =IF(S3="","",S3+N(T3)+N(U3)+N(V3)+N(W3)) -> 23 | Y3: Vinted | AA3: 391 | AC3: Sold | AE3: 313 | AF3: 313 | AH3: =IF(AND(AC3="Sold",AE3<>"",AF3<>""),AE3-AF3,"") -> 0 | AI3: =IF(AND(AC3="Sold",AF3<>"",X3<>""),AF3-N(AG3)-X3,"") -> 290 | AJ3: =IF(AND(AI3<>"",N(AE3)>0),AI3/AE3,"") -> 0.92651757 | AK3: =IF(AND(AI3<>"",N(X3)>0),AI3/X3,"") -> 12.608696 | AL3: =IF(AND(AC3="Sold",AD3<>"",Z3<>""),AD3-Z3,"") | AM3: =IF(AND(AC3="Sold",N(AA3)>0,AE3<>""),1-AE3/AA3,"") -> 0.19948849 | AN3: =IF(AND(AC3<>"Sold",AC3<>"",Z3<>""),TODAY()-Z3,"") | AO3: Exact | AP3: Purchase date had day and month swapped in the original sheet; corrected.
A4: DEMO-002 | B4: Louis Vuitton | E4: Brown | F4: Leather | H4: Fair | K4: Supplier A | L4: Clearance lot | M4: LOT-A | N4: 307 | O4: 46215 | P4: 31 | Q4: GBP | R4: 1 | S4: =IF(OR(P4="",R4=""),"",P4*R4) -> 31 | T4: 11 | U4: 0 | V4: 0 | W4: 0 | X4: =IF(S4="","",S4+N(T4)+N(U4)+N(V4)+N(W4)) -> 42 | Y4: Vinted | AA4: 153 | AC4: Sold | AE4: 102 | AF4: 102 | AH4: =IF(AND(AC4="Sold",AE4<>"",AF4<>""),AE4-AF4,"") -> 0 | AI4: =IF(AND(AC4="Sold",AF4<>"",X4<>""),AF4-N(AG4)-X4,"") -> 60 | AJ4: =IF(AND(AI4<>"",N(AE4)>0),AI4/AE4,"") -> 0.58823529 | AK4: =IF(AND(AI4<>"",N(X4)>0),AI4/X4,"") -> 1.4285714 | AL4: =IF(AND(AC4="Sold",AD4<>"",Z4<>""),AD4-Z4,"") | AM4: =IF(AND(AC4="Sold",N(AA4)>0,AE4<>""),1-AE4/AA4,"") -> 0.33333333 | AN4: =IF(AND(AC4<>"Sold",AC4<>"",Z4<>""),TODAY()-Z4,"") | AO4: Estimated | AP4: Platform fee not recorded in the original sheet. Model field held a condition or year rather than a model name. Purchase date had day and month swapped in the original sheet; corrected.
A5: DEMO-003 | B5: Dior | C5: Vintage with strap | E5: Multi | F5: Canvas | H5: Satisfactory | K5: Supplier A | L5: Clearance lot | M5: LOT-A | N5: 306 | O5: 46215 | P5: 10 | Q5: GBP | R5: 1 | S5: =IF(OR(P5="",R5=""),"",P5*R5) -> 10 | T5: 11 | U5: 0 | V5: 0 | W5: 0 | X5: =IF(S5="","",S5+N(T5)+N(U5)+N(V5)+N(W5)) -> 21 | Y5: Vinted | AA5: 255 | AC5: Sold | AE5: 204 | AF5: 204 | AH5: =IF(AND(AC5="Sold",AE5<>"",AF5<>""),AE5-AF5,"") -> 0 | AI5: =IF(AND(AC5="Sold",AF5<>"",X5<>""),AF5-N(AG5)-X5,"") -> 183 | AJ5: =IF(AND(AI5<>"",N(AE5)>0),AI5/AE5,"") -> 0.89705882 | AK5: =IF(AND(AI5<>"",N(X5)>0),AI5/X5,"") -> 8.7142857 | AL5: =IF(AND(AC5="Sold",AD5<>"",Z5<>""),AD5-Z5,"") | AM5: =IF(AND(AC5="Sold",N(AA5)>0,AE5<>""),1-AE5/AA5,"") -> 0.2 | AN5: =IF(AND(AC5<>"Sold",AC5<>"",Z5<>""),TODAY()-Z5,"") | AO5: Exact | AP5: Purchase date had day and month swapped in the original sheet; corrected.
A6: DEMO-004 | B6: Gucci | C6: Tote bag with toys | E6: Multi | F6: Leather | H6: Good | K6: Supplier A | L6: Clearance lot | M6: LOT-A | N6: 333 | O6: 46215 | P6: 33 | Q6: GBP | R6: 1 | S6: =IF(OR(P6="",R6=""),"",P6*R6) -> 33 | T6: 12 | U6: 0 | V6: 0 | W6: 0 | X6: =IF(S6="","",S6+N(T6)+N(U6)+N(V6)+N(W6)) -> 45 | Y6: Vinted | AA6: 222 | AC6: Sold | AE6: 139 | AF6: 139 | AH6: =IF(AND(AC6="Sold",AE6<>"",AF6<>""),AE6-AF6,"") -> 0 | AI6: =IF(AND(AC6="Sold",AF6<>"",X6<>""),AF6-N(AG6)-X6,"") -> 94 | AJ6: =IF(AND(AI6<>"",N(AE6)>0),AI6/AE6,"") -> 0.67625899 | AK6: =IF(AND(AI6<>"",N(X6)>0),AI6/X6,"") -> 2.0888889 | AL6: =IF(AND(AC6="Sold",AD6<>"",Z6<>""),AD6-Z6,"") | AM6: =IF(AND(AC6="Sold",N(AA6)>0,AE6<>""),1-AE6/AA6,"") -> 0.37387387 | AN6: =IF(AND(AC6<>"Sold",AC6<>"",Z6<>""),TODAY()-Z6,"") | AO6: Estimated | AP6: Platform fee not recorded in the original sheet. Purchase date had day and month swapped in the original sheet; corrected.
A7: DEMO-005 | B7: Bottega Veneta | E7: Purple | F7: Leather | H7: Satisfactory | K7: Supplier A | L7: Clearance lot | M7: LOT-A | N7: 260 | O7: 46204 | P7: 35 | Q7: GBP | R7: 1 | S7: =IF(OR(P7="",R7=""),"",P7*R7) -> 35 | T7: 10 | U7: 0 | V7: 0 | W7: 0 | X7: =IF(S7="","",S7+N(T7)+N(U7)+N(V7)+N(W7)) -> 45 | Y7: eBay | AA7: 87 | AC7: Sold | AE7: 61 | AF7: 52 | AH7: =IF(AND(AC7="Sold",AE7<>"",AF7<>""),AE7-AF7,"") -> 9 | AI7: =IF(AND(AC7="Sold",AF7<>"",X7<>""),AF7-N(AG7)-X7,"") -> 7 | AJ7: =IF(AND(AI7<>"",N(AE7)>0),AI7/AE7,"") -> 0.1147541 | AK7: =IF(AND(AI7<>"",N(X7)>0),AI7/X7,"") -> 0.15555556 | AL7: =IF(AND(AC7="Sold",AD7<>"",Z7<>""),AD7-Z7,"") | AM7: =IF(AND(AC7="Sold",N(AA7)>0,AE7<>""),1-AE7/AA7,"") -> 0.29885057 | AN7: =IF(AND(AC7<>"Sold",AC7<>"",Z7<>""),TODAY()-Z7,"") | AO7: Exact | AP7: Purchase date had day and month swapped in the original sheet; corrected.
A8: DEMO-006 | B8: Fendi | E8: Brown | F8: Cotton | H8: Satisfactory | K8: Supplier A | L8: Clearance lot | M8: LOT-A | N8: 266 | O8: 46215 | P8: 9 | Q8: GBP | R8: 1 | S8: =IF(OR(P8="",R8=""),"",P8*R8) -> 9 | T8: 10 | U8: 0 | V8: 0 | W8: 0 | X8: =IF(S8="","",S8+N(T8)+N(U8)+N(V8)+N(W8)) -> 19 | Y8: Depop | AA8: 89 | AC8: Sold | AE8: 133 | AF8: 133 | AH8: =IF(AND(AC8="Sold",AE8<>"",AF8<>""),AE8-AF8,"") -> 0 | AI8: =IF(AND(AC8="Sold",AF8<>"",X8<>""),AF8-N(AG8)-X8,"") -> 114 | AJ8: =IF(AND(AI8<>"",N(AE8)>0),AI8/AE8,"") -> 0.85714286 | AK8: =IF(AND(AI8<>"",N(X8)>0),AI8/X8,"") -> 6 | AL8: =IF(AND(AC8="Sold",AD8<>"",Z8<>""),AD8-Z8,"") | AM8: =IF(AND(AC8="Sold",N(AA8)>0,AE8<>""),1-AE8/AA8,"") -> -0.49438202 | AN8: =IF(AND(AC8<>"Sold",AC8<>"",Z8<>""),TODAY()-Z8,"") | AO8: Exact | AP8: Platform fee not recorded in the original sheet. Sold above its first list price: listed price to check. Model field held a condition or year rather than a model name. Purchase date had day and month swapped in the original sheet; corrected.
A9: DEMO-007 | B9: Bottega Veneta | E9: Green | F9: Leather | H9: Good | K9: Supplier A | L9: Clearance lot | M9: LOT-A | N9: 261 | O9: 46215 | P9: 26 | Q9: GBP | R9: 1 | S9: =IF(OR(P9="",R9=""),"",P9*R9) -> 26 | T9: 10 | U9: 0 | V9: 0 | W9: 0 | X9: =IF(S9="","",S9+N(T9)+N(U9)+N(V9)+N(W9)) -> 36 | Y9: Depop | AA9: 87 | AC9: Sold | AE9: 174 | AF9: 174 | AH9: =IF(AND(AC9="Sold",AE9<>"",AF9<>""),AE9-AF9,"") -> 0 | AI9: =IF(AND(AC9="Sold",AF9<>"",X9<>""),AF9-N(AG9)-X9,"") -> 138 | AJ9: =IF(AND(AI9<>"",N(AE9)>0),AI9/AE9,"") -> 0.79310345 | AK9: =IF(AND(AI9<>"",N(X9)>0),AI9/X9,"") -> 3.8333333 | AL9: =IF(AND(AC9="Sold",AD9<>"",Z9<>""),AD9-Z9,"") | AM9: =IF(AND(AC9="Sold",N(AA9)>0,AE9<>""),1-AE9/AA9,"") -> -1 | AN9: =IF(AND(AC9<>"Sold",AC9<>"",Z9<>""),TODAY()-Z9,"") | AO9: Estimated | AP9: Platform fee not recorded in the original sheet. Sold above its first list price: listed price to check. Purchase date had day and month swapped in the original sheet; corrected.
A10: DEMO-008 | B10: Bottega Veneta | E10: Blue | F10: Leather | H10: Satisfactory | K10: Supplier A | L10: Clearance lot | M10: LOT-A | N10: 299 | O10: 46215 | P10: 30 | Q10: GBP | R10: 1 | S10: =IF(OR(P10="",R10=""),"",P10*R10) -> 30 | T10: 11 | U10: 0 | V10: 0 | W10: 0 | X10: =IF(S10="","",S10+N(T10)+N(U10)+N(V10)+N(W10)) -> 41 | Y10: Depop | AA10: 100 | AC10: Sold | AE10: 150 | AF10: 150 | AH10: =IF(AND(AC10="Sold",AE10<>"",AF10<>""),AE10-AF10,"") -> 0 | AI10: =IF(AND(AC10="Sold",AF10<>"",X10<>""),AF10-N(AG10)-X10,"") -> 109 | AJ10: =IF(AND(AI10<>"",N(AE10)>0),AI10/AE10,"") -> 0.72666667 | AK10: =IF(AND(AI10<>"",N(X10)>0),AI10/X10,"") -> 2.6585366 | AL10: =IF(AND(AC10="Sold",AD10<>"",Z10<>""),AD10-Z10,"") | AM10: =IF(AND(AC10="Sold",N(AA10)>0,AE10<>""),1-AE10/AA10,"") -> -0.5 | AN10: =IF(AND(AC10<>"Sold",AC10<>"",Z10<>""),TODAY()-Z10,"") | AO10: Estimated | AP10: Platform fee not recorded in the original sheet. Sold above its first list price: listed price to check. Purchase date had day and month swapped in the original sheet; corrected.
A11: DEMO-009 | B11: Louis Vuitton | E11: Silver | F11: Leather | H11: Satisfactory | K11: Supplier A | L11: Clearance lot | M11: LOT-A | N11: 266 | O11: 46215 | P11: 9 | Q11: GBP | R11: 1 | S11: =IF(OR(P11="",R11=""),"",P11*R11) -> 9 | T11: 10 | U11: 0 | V11: 0 | W11: 0 | X11: =IF(S11="","",S11+N(T11)+N(U11)+N(V11)+N(W11)) -> 19 | Y11: Depop | AA11: 89 | AC11: Sold | AE11: 133 | AF11: 133 | AH11: =IF(AND(AC11="Sold",AE11<>"",AF11<>""),AE11-AF11,"") -> 0 | AI11: =IF(AND(AC11="Sold",AF11<>"",X11<>""),AF11-N(AG11)-X11,"") -> 114 | AJ11: =IF(AND(AI11<>"",N(AE11)>0),AI11/AE11,"") -> 0.85714286 | AK11: =IF(AND(AI11<>"",N(X11)>0),AI11/X11,"") -> 6 | AL11: =IF(AND(AC11="Sold",AD11<>"",Z11<>""),AD11-Z11,"") | AM11: =IF(AND(AC11="Sold",N(AA11)>0,AE11<>""),1-AE11/AA11,"") -> -0.49438202 | AN11: =IF(AND(AC11<>"Sold",AC11<>"",Z11<>""),TODAY()-Z11,"") | AO11: Estimated | AP11: Platform fee not recorded in the original sheet. Purchase date had day and month swapped in the original sheet; corrected.
A12: DEMO-010 | B12: Gucci | C12: Bamboo | F12: Leather | H12: Satisfactory | K12: Supplier A | L12: Clearance lot | M12: LOT-A | N12: 313 | O12: 46215 | P12: 10 | Q12: GBP | R12: 1 | S12: =IF(OR(P12="",R12=""),"",P12*R12) -> 10 | T12: 11 | U12: 0 | V12: 0 | W12: 0 | X12: =IF(S12="","",S12+N(T12)+N(U12)+N(V12)+N(W12)) -> 21 | Y12: Depop | AA12: 104 | AC12: Sold | AE12: 188 | AF12: 188 | AH12: =IF(AND(AC12="Sold",AE12<>"",AF12<>""),AE12-AF12,"") -> 0 | AI12: =IF(AND(AC12="Sold",AF12<>"",X12<>""),AF12-N(AG12)-X12,"") -> 167 | AJ12: =IF(AND(AI12<>"",N(AE12)>0),AI12/AE12,"") -> 0.88829787 | AK12: =IF(AND(AI12<>"",N(X12)>0),AI12/X12,"") -> 7.952381 | AL12: =IF(AND(AC12="Sold",AD12<>"",Z12<>""),AD12-Z12,"") | AM12: =IF(AND(AC12="Sold",N(AA12)>0,AE12<>""),1-AE12/AA12,"") -> -0.80769231 | AN12: =IF(AND(AC12<>"Sold",AC12<>"",Z12<>""),TODAY()-Z12,"") | AO12: Estimated | AP12: Platform fee not recorded in the original sheet. Sold above its first list price: listed price to check. Purchase date had day and month swapped in the original sheet; corrected.
A13: DEMO-011 | B13: Louis Vuitton | E13: Yellow | F13: Suede | H13: Satisfactory | K13: Supplier A | L13: Clearance lot | M13: LOT-A | N13: 264 | O13: 46215 | P13: 9 | Q13: GBP | R13: 1 | S13: =IF(OR(P13="",R13=""),"",P13*R13) -> 9 | T13: 10 | U13: 0 | V13: 0 | W13: 0 | X13: =IF(S13="","",S13+N(T13)+N(U13)+N(V13)+N(W13)) -> 19 | Y13: Depop | AA13: 88 | AC13: Sold | AE13: 176 | AF13: 176 | AH13: =IF(AND(AC13="Sold",AE13<>"",AF13<>""),AE13-AF13,"") -> 0 | AI13: =IF(AND(AC13="Sold",AF13<>"",X13<>""),AF13-N(AG13)-X13,"") -> 157 | AJ13: =IF(AND(AI13<>"",N(AE13)>0),AI13/AE13,"") -> 0.89204545 | AK13: =IF(AND(AI13<>"",N(X13)>0),AI13/X13,"") -> 8.2631579 | AL13: =IF(AND(AC13="Sold",AD13<>"",Z13<>""),AD13-Z13,"") | AM13: =IF(AND(AC13="Sold",N(AA13)>0,AE13<>""),1-AE13/AA13,"") -> -1 | AN13: =IF(AND(AC13<>"Sold",AC13<>"",Z13<>""),TODAY()-Z13,"") | AO13: Estimated | AP13: Platform fee not recorded in the original sheet. Sold above its first list price: listed price to check. Purchase date had day and month swapped in the original sheet; corrected.
A14: DEMO-012 | B14: Dior | C14: Bowling | E14: Black | F14: Canvas | H14: Good | J14: Platform authenticated | K14: Supplier B | L14: Selected single | M14: SINGLE-A | N14: 244 | O14: 46223 | P14: 244 | Q14: GBP | R14: 1 | S14: =IF(OR(P14="",R14=""),"",P14*R14) -> 244 | T14: 49 | U14: 0 | V14: 0 | W14: 0 | X14: =IF(S14="","",S14+N(T14)+N(U14)+N(V14)+N(W14)) -> 293 | Y14: Vestiaire Collective | AA14: 1229 | AC14: Sold | AE14: 614 | AF14: 497 | AH14: =IF(AND(AC14="Sold",AE14<>"",AF14<>""),AE14-AF14,"") -> 117 | AI14: =IF(AND(AC14="Sold",AF14<>"",X14<>""),AF14-N(AG14)-X14,"") -> 204 | AJ14: =IF(AND(AI14<>"",N(AE14)>0),AI14/AE14,"") -> 0.33224756 | AK14: =IF(AND(AI14<>"",N(X14)>0),AI14/X14,"") -> 0.69624573 | AL14: =IF(AND(AC14="Sold",AD14<>"",Z14<>""),AD14-Z14,"") | AM14: =IF(AND(AC14="Sold",N(AA14)>0,AE14<>""),1-AE14/AA14,"") -> 0.50040683 | AN14: =IF(AND(AC14<>"Sold",AC14<>"",Z14<>""),TODAY()-Z14,"") | AO14: Exact | AP14: Bought individually from a second supplier, not part of the clearance lot.
A15: DEMO-013 | B15: Bottega Veneta | C15: Andiamo | E15: Brown | F15: Canvas/leather | H15: Good | K15: Supplier A | L15: Clearance lot | M15: LOT-A | N15: 334 | O15: 46215 | P15: 33 | Q15: GBP | R15: 1 | S15: =IF(OR(P15="",R15=""),"",P15*R15) -> 33 | T15: 12 | U15: 0 | V15: 0 | W15: 0 | X15: =IF(S15="","",S15+N(T15)+N(U15)+N(V15)+N(W15)) -> 45 | Y15: Depop | AA15: 334 | AC15: Listed | AH15: =IF(AND(AC15="Sold",AE15<>"",AF15<>""),AE15-AF15,"") | AI15: =IF(AND(AC15="Sold",AF15<>"",X15<>""),AF15-N(AG15)-X15,"") | AJ15: =IF(AND(AI15<>"",N(AE15)>0),AI15/AE15,"") | AK15: =IF(AND(AI15<>"",N(X15)>0),AI15/X15,"") | AL15: =IF(AND(AC15="Sold",AD15<>"",Z15<>""),AD15-Z15,"") | AM15: =IF(AND(AC15="Sold",N(AA15)>0,AE15<>""),1-AE15/AA15,"") | AN15: =IF(AND(AC15<>"Sold",AC15<>"",Z15<>""),TODAY()-Z15,"") | AO15: Estimated | AP15: Purchase date had day and month swapped in the original sheet; corrected.
A16: DEMO-014 | B16: Chanel | E16: Pink | F16: Leather | H16: Satisfactory | K16: Supplier A | L16: Clearance lot | M16: LOT-A | N16: 273 | O16: 46215 | P16: 9 | Q16: GBP | R16: 1 | S16: =IF(OR(P16="",R16=""),"",P16*R16) -> 9 | T16: 10 | U16: 0 | V16: 0 | W16: 0 | X16: =IF(S16="","",S16+N(T16)+N(U16)+N(V16)+N(W16)) -> 19 | Y16: Private / direct | AA16: 908 | AC16: Sold | AE16: 336 | AF16: 336 | AH16: =IF(AND(AC16="Sold",AE16<>"",AF16<>""),AE16-AF16,"") -> 0 | AI16: =IF(AND(AC16="Sold",AF16<>"",X16<>""),AF16-N(AG16)-X16,"") -> 317 | AJ16: =IF(AND(AI16<>"",N(AE16)>0),AI16/AE16,"") -> 0.94345238 | AK16: =IF(AND(AI16<>"",N(X16)>0),AI16/X16,"") -> 16.684211 | AL16: =IF(AND(AC16="Sold",AD16<>"",Z16<>""),AD16-Z16,"") | AM16: =IF(AND(AC16="Sold",N(AA16)>0,AE16<>""),1-AE16/AA16,"") -> 0.62995595 | AN16: =IF(AND(AC16<>"Sold",AC16<>"",Z16<>""),TODAY()-Z16,"") | AO16: Estimated | AP16: Sold privately to a personal contact, not through a platform. Purchase date had day and month swapped in the original sheet; corrected.
A17: DEMO-015 | B17: Gucci | E17: Gold | F17: Ostrich leather | H17: Satisfactory | J17: Platform authenticated | K17: Supplier A | L17: Clearance lot | M17: LOT-A | N17: 344 | O17: 46235 | P17: 46 | Q17: GBP | R17: 1 | S17: =IF(OR(P17="",R17=""),"",P17*R17) -> 46 | T17: 13 | U17: 0 | V17: 0 | W17: 0 | X17: =IF(S17="","",S17+N(T17)+N(U17)+N(V17)+N(W17)) -> 59 | Y17: Vestiaire Collective | AA17: 689 | AC17: Sold | AE17: 422 | AF17: 341 | AG17: 0 | AH17: =IF(AND(AC17="Sold",AE17<>"",AF17<>""),AE17-AF17,"") -> 81 | AI17: =IF(AND(AC17="Sold",AF17<>"",X17<>""),AF17-N(AG17)-X17,"") -> 282 | AJ17: =IF(AND(AI17<>"",N(AE17)>0),AI17/AE17,"") -> 0.66824645 | AK17: =IF(AND(AI17<>"",N(X17)>0),AI17/X17,"") -> 4.779661 | AL17: =IF(AND(AC17="Sold",AD17<>"",Z17<>""),AD17-Z17,"") | AM17: =IF(AND(AC17="Sold",N(AA17)>0,AE17<>""),1-AE17/AA17,"") -> 0.38751814 | AN17: =IF(AND(AC17<>"Sold",AC17<>"",Z17<>""),TODAY()-Z17,"") | AO17: Estimated | AP17: Added in the founder's updated sheet.
A18: DEMO-016 | B18: Loewe | C18: Amazona burgundy leather | E18: Burgundy | F18: Leather | H18: Satisfactory | K18: Supplier C | L18: Clearance lot | M18: LOT-B | N18: 1863 | O18: 46235 | P18: 68 | Q18: GBP | R18: 1 | S18: =IF(OR(P18="",R18=""),"",P18*R18) -> 68 | T18: 7 | U18: 4 | V18: 0 | W18: 0 | X18: =IF(S18="","",S18+N(T18)+N(U18)+N(V18)+N(W18)) -> 79 | Y18: Vestiaire Collective | AA18: 147 | AC18: Sold | AE18: 118 | AF18: 100 | AG18: 0 | AH18: =IF(AND(AC18="Sold",AE18<>"",AF18<>""),AE18-AF18,"") -> 18 | AI18: =IF(AND(AC18="Sold",AF18<>"",X18<>""),AF18-N(AG18)-X18,"") -> 21 | AJ18: =IF(AND(AI18<>"",N(AE18)>0),AI18/AE18,"") -> 0.1779661 | AK18: =IF(AND(AI18<>"",N(X18)>0),AI18/X18,"") -> 0.26582278 | AL18: =IF(AND(AC18="Sold",AD18<>"",Z18<>""),AD18-Z18,"") | AM18: =IF(AND(AC18="Sold",N(AA18)>0,AE18<>""),1-AE18/AA18,"") -> 0.19727891 | AN18: =IF(AND(AC18<>"Sold",AC18<>"",Z18<>""),TODAY()-Z18,"") | AO18: Estimated | AP18: Purchase date had day and month swapped in the original sheet; corrected. Per-bag costs in this lot were split in proportion to sale price; judge the lot as a whole. Platform fee recorded as exactly 15% of the sale; to confirm against the payout.
A19: DEMO-017 | B19: Loewe | C19: Brown leather flap crossbody | E19: Tan | F19: Leather | H19: Satisfactory | K19: Supplier C | L19: Clearance lot | M19: LOT-B | N19: 2029 | O19: 46235 | P19: 52 | Q19: GBP | R19: 1 | S19: =IF(OR(P19="",R19=""),"",P19*R19) -> 52 | T19: 8 | U19: 4 | V19: 0 | W19: 0 | X19: =IF(S19="","",S19+N(T19)+N(U19)+N(V19)+N(W19)) -> 64 | Y19: Vestiaire Collective | AA19: 112 | AC19: Sold | AE19: 90 | AF19: 76 | AG19: 0 | AH19: =IF(AND(AC19="Sold",AE19<>"",AF19<>""),AE19-AF19,"") -> 14 | AI19: =IF(AND(AC19="Sold",AF19<>"",X19<>""),AF19-N(AG19)-X19,"") -> 12 | AJ19: =IF(AND(AI19<>"",N(AE19)>0),AI19/AE19,"") -> 0.13333333 | AK19: =IF(AND(AI19<>"",N(X19)>0),AI19/X19,"") -> 0.1875 | AL19: =IF(AND(AC19="Sold",AD19<>"",Z19<>""),AD19-Z19,"") | AM19: =IF(AND(AC19="Sold",N(AA19)>0,AE19<>""),1-AE19/AA19,"") -> 0.19642857 | AN19: =IF(AND(AC19<>"Sold",AC19<>"",Z19<>""),TODAY()-Z19,"") | AO19: Estimated | AP19: Purchase date had day and month swapped in the original sheet; corrected. Per-bag costs in this lot were split in proportion to sale price; judge the lot as a whole. Platform fee recorded as exactly 15% of the sale; to confirm against the payout.
A20: DEMO-018 | B20: Dior | C20: Bowling bag | E20: Pink | F20: Leather | H20: Satisfactory | K20: Supplier C | L20: Clearance lot | M20: LOT-B | N20: 1746 | O20: 46235 | P20: 233 | Q20: GBP | R20: 1 | S20: =IF(OR(P20="",R20=""),"",P20*R20) -> 233 | T20: 7 | U20: 3 | V20: 0 | W20: 0 | X20: =IF(S20="","",S20+N(T20)+N(U20)+N(V20)+N(W20)) -> 243 | Y20: Vestiaire Collective | AA20: 504 | AC20: Sold | AE20: 404 | AF20: 343 | AG20: 0 | AH20: =IF(AND(AC20="Sold",AE20<>"",AF20<>""),AE20-AF20,"") -> 61 | AI20: =IF(AND(AC20="Sold",AF20<>"",X20<>""),AF20-N(AG20)-X20,"") -> 100 | AJ20: =IF(AND(AI20<>"",N(AE20)>0),AI20/AE20,"") -> 0.24752475 | AK20: =IF(AND(AI20<>"",N(X20)>0),AI20/X20,"") -> 0.41152263 | AL20: =IF(AND(AC20="Sold",AD20<>"",Z20<>""),AD20-Z20,"") | AM20: =IF(AND(AC20="Sold",N(AA20)>0,AE20<>""),1-AE20/AA20,"") -> 0.1984127 | AN20: =IF(AND(AC20<>"Sold",AC20<>"",Z20<>""),TODAY()-Z20,"") | AO20: Estimated | AP20: Purchase date had day and month swapped in the original sheet; corrected. Per-bag costs in this lot were split in proportion to sale price; judge the lot as a whole. Platform fee recorded as exactly 15% of the sale; to confirm against the payout.
A21: DEMO-019 | B21: Dior | C21: Leather handbag | E21: Brown | F21: Leather | H21: Good | K21: Supplier C | L21: Clearance lot | M21: LOT-B | N21: 2274 | O21: 46235 | P21: 386 | Q21: GBP | R21: 1 | S21: =IF(OR(P21="",R21=""),"",P21*R21) -> 386 | T21: 9 | U21: 4 | V21: 0 | W21: 0 | X21: =IF(S21="","",S21+N(T21)+N(U21)+N(V21)+N(W21)) -> 399 | Y21: Vestiaire Collective | AA21: 837 | AC21: Sold | AE21: 669 | AF21: 569 | AG21: 0 | AH21: =IF(AND(AC21="Sold",AE21<>"",AF21<>""),AE21-AF21,"") -> 100 | AI21: =IF(AND(AC21="Sold",AF21<>"",X21<>""),AF21-N(AG21)-X21,"") -> 170 | AJ21: =IF(AND(AI21<>"",N(AE21)>0),AI21/AE21,"") -> 0.25411061 | AK21: =IF(AND(AI21<>"",N(X21)>0),AI21/X21,"") -> 0.42606516 | AL21: =IF(AND(AC21="Sold",AD21<>"",Z21<>""),AD21-Z21,"") | AM21: =IF(AND(AC21="Sold",N(AA21)>0,AE21<>""),1-AE21/AA21,"") -> 0.20071685 | AN21: =IF(AND(AC21<>"Sold",AC21<>"",Z21<>""),TODAY()-Z21,"") | AO21: Estimated | AP21: Purchase date had day and month swapped in the original sheet; corrected. Per-bag costs in this lot were split in proportion to sale price; judge the lot as a whole. Platform fee recorded as exactly 15% of the sale; to confirm against the payout.
A22: DEMO-020 | B22: Loewe | C22: Champagne monogram bowling tote | E22: Champagne | F22: Coated canvas / leather | H22: Satisfactory | K22: Supplier C | L22: Clearance lot | M22: LOT-B | N22: 2328 | O22: 46235 | P22: 175 | Q22: GBP | R22: 1 | S22: =IF(OR(P22="",R22=""),"",P22*R22) -> 175 | T22: 9 | U22: 5 | V22: 0 | W22: 0 | X22: =IF(S22="","",S22+N(T22)+N(U22)+N(V22)+N(W22)) -> 189 | Y22: Vestiaire Collective | AA22: 380 | AC22: Sold | AE22: 304 | AF22: 258 | AG22: 0 | AH22: =IF(AND(AC22="Sold",AE22<>"",AF22<>""),AE22-AF22,"") -> 46 | AI22: =IF(AND(AC22="Sold",AF22<>"",X22<>""),AF22-N(AG22)-X22,"") -> 69 | AJ22: =IF(AND(AI22<>"",N(AE22)>0),AI22/AE22,"") -> 0.22697368 | AK22: =IF(AND(AI22<>"",N(X22)>0),AI22/X22,"") -> 0.36507937 | AL22: =IF(AND(AC22="Sold",AD22<>"",Z22<>""),AD22-Z22,"") | AM22: =IF(AND(AC22="Sold",N(AA22)>0,AE22<>""),1-AE22/AA22,"") -> 0.2 | AN22: =IF(AND(AC22<>"Sold",AC22<>"",Z22<>""),TODAY()-Z22,"") | AO22: Estimated | AP22: Purchase date had day and month swapped in the original sheet; corrected. Per-bag costs in this lot were split in proportion to sale price; judge the lot as a whole. Platform fee recorded as exactly 15% of the sale; to confirm against the payout.
A23: DEMO-021 | B23: Gucci | C23: Ostrich bag | E23: Black | F23: Leather | H23: Satisfactory | K23: Supplier C | L23: Clearance lot | M23: LOT-B | N23: 2068 | O23: 46235 | P23: 205 | Q23: GBP | R23: 1 | S23: =IF(OR(P23="",R23=""),"",P23*R23) -> 205 | T23: 8 | U23: 4 | V23: 0 | W23: 0 | X23: =IF(S23="","",S23+N(T23)+N(U23)+N(V23)+N(W23)) -> 217 | Y23: Vestiaire Collective | AA23: 445 | AC23: Sold | AE23: 356 | AF23: 302 | AG23: 0 | AH23: =IF(AND(AC23="Sold",AE23<>"",AF23<>""),AE23-AF23,"") -> 54 | AI23: =IF(AND(AC23="Sold",AF23<>"",X23<>""),AF23-N(AG23)-X23,"") -> 85 | AJ23: =IF(AND(AI23<>"",N(AE23)>0),AI23/AE23,"") -> 0.23876404 | AK23: =IF(AND(AI23<>"",N(X23)>0),AI23/X23,"") -> 0.39170507 | AL23: =IF(AND(AC23="Sold",AD23<>"",Z23<>""),AD23-Z23,"") | AM23: =IF(AND(AC23="Sold",N(AA23)>0,AE23<>""),1-AE23/AA23,"") -> 0.2 | AN23: =IF(AND(AC23<>"Sold",AC23<>"",Z23<>""),TODAY()-Z23,"") | AO23: Estimated | AP23: Purchase date had day and month swapped in the original sheet; corrected. Purchase price was typed with a comma decimal, so the original sheet left it out of cost; fixed. Per-bag costs in this lot were split in proportion to sale price; judge the lot as a whole. Platform fee recorded as exactly 15% of the sale; to confirm against the payout.
A24: DEMO-022 | B24: Chanel | C24: Precision pink terrycloth shoulder bag | E24: Chocolate brown | F24: Plastic | H24: Good | K24: Supplier C | L24: Clearance lot | M24: LOT-B | N24: 2224 | O24: 46235 | P24: 63 | Q24: GBP | R24: 1 | S24: =IF(OR(P24="",R24=""),"",P24*R24) -> 63 | T24: 9 | U24: 4 | V24: 0 | W24: 0 | X24: =IF(S24="","",S24+N(T24)+N(U24)+N(V24)+N(W24)) -> 76 | Y24: Vestiaire Collective | AA24: 136 | AC24: Sold | AE24: 109 | AF24: 93 | AG24: 0 | AH24: =IF(AND(AC24="Sold",AE24<>"",AF24<>""),AE24-AF24,"") -> 16 | AI24: =IF(AND(AC24="Sold",AF24<>"",X24<>""),AF24-N(AG24)-X24,"") -> 17 | AJ24: =IF(AND(AI24<>"",N(AE24)>0),AI24/AE24,"") -> 0.1559633 | AK24: =IF(AND(AI24<>"",N(X24)>0),AI24/X24,"") -> 0.22368421 | AL24: =IF(AND(AC24="Sold",AD24<>"",Z24<>""),AD24-Z24,"") | AM24: =IF(AND(AC24="Sold",N(AA24)>0,AE24<>""),1-AE24/AA24,"") -> 0.19852941 | AN24: =IF(AND(AC24<>"Sold",AC24<>"",Z24<>""),TODAY()-Z24,"") | AO24: Estimated | AP24: Purchase date had day and month swapped in the original sheet; corrected. Per-bag costs in this lot were split in proportion to sale price; judge the lot as a whole. Platform fee recorded as exactly 15% of the sale; to confirm against the payout.
A25: DEMO-023 | B25: Gucci | C25: Ophidia tote | E25: Navy | F25: Canvas / leather | H25: Satisfactory | K25: Supplier C | L25: Clearance lot | M25: LOT-B | N25: 1938 | O25: 46235 | P25: 157 | Q25: GBP | R25: 1 | S25: =IF(OR(P25="",R25=""),"",P25*R25) -> 157 | T25: 8 | U25: 4 | V25: 0 | W25: 0 | X25: =IF(S25="","",S25+N(T25)+N(U25)+N(V25)+N(W25)) -> 169 | Y25: Vestiaire Collective | AA25: 342 | AC25: Sold | AE25: 273 | AF25: 232 | AG25: 0 | AH25: =IF(AND(AC25="Sold",AE25<>"",AF25<>""),AE25-AF25,"") -> 41 | AI25: =IF(AND(AC25="Sold",AF25<>"",X25<>""),AF25-N(AG25)-X25,"") -> 63 | AJ25: =IF(AND(AI25<>"",N(AE25)>0),AI25/AE25,"") -> 0.23076923 | AK25: =IF(AND(AI25<>"",N(X25)>0),AI25/X25,"") -> 0.37278107 | AL25: =IF(AND(AC25="Sold",AD25<>"",Z25<>""),AD25-Z25,"") | AM25: =IF(AND(AC25="Sold",N(AA25)>0,AE25<>""),1-AE25/AA25,"") -> 0.20175439 | AN25: =IF(AND(AC25<>"Sold",AC25<>"",Z25<>""),TODAY()-Z25,"") | AO25: Estimated | AP25: Purchase date had day and month swapped in the original sheet; corrected. Per-bag costs in this lot were split in proportion to sale price; judge the lot as a whole. Platform fee recorded as exactly 15% of the sale; to confirm against the payout.
A26: DEMO-024 | B26: Loewe | C26: Amazona vintage | E26: Cream | F26: Leather | H26: Satisfactory | K26: Supplier C | L26: Clearance lot | M26: LOT-B | N26: 2060 | O26: 46235 | P26: 177 | Q26: GBP | R26: 1 | S26: =IF(OR(P26="",R26=""),"",P26*R26) -> 177 | T26: 8 | U26: 4 | V26: 0 | W26: 0 | X26: =IF(S26="","",S26+N(T26)+N(U26)+N(V26)+N(W26)) -> 189 | Y26: Vestiaire Collective | AA26: 385 | AC26: Sold | AE26: 308 | AF26: 262 | AG26: 0 | AH26: =IF(AND(AC26="Sold",AE26<>"",AF26<>""),AE26-AF26,"") -> 46 | AI26: =IF(AND(AC26="Sold",AF26<>"",X26<>""),AF26-N(AG26)-X26,"") -> 73 | AJ26: =IF(AND(AI26<>"",N(AE26)>0),AI26/AE26,"") -> 0.23701299 | AK26: =IF(AND(AI26<>"",N(X26)>0),AI26/X26,"") -> 0.38624339 | AL26: =IF(AND(AC26="Sold",AD26<>"",Z26<>""),AD26-Z26,"") | AM26: =IF(AND(AC26="Sold",N(AA26)>0,AE26<>""),1-AE26/AA26,"") -> 0.2 | AN26: =IF(AND(AC26<>"Sold",AC26<>"",Z26<>""),TODAY()-Z26,"") | AO26: Estimated | AP26: Purchase date had day and month swapped in the original sheet; corrected. Per-bag costs in this lot were split in proportion to sale price; judge the lot as a whole. Platform fee recorded as exactly 15% of the sale; to confirm against the payout.
A27: DEMO-025 | B27: Miu Miu | C27: Bow bag | E27: Red | F27: Leather | H27: Satisfactory | K27: Supplier C | L27: Clearance lot | M27: LOT-B | N27: 1997 | O27: 46235 | P27: 195 | Q27: GBP | R27: 1 | S27: =IF(OR(P27="",R27=""),"",P27*R27) -> 195 | T27: 8 | U27: 4 | V27: 0 | W27: 0 | X27: =IF(S27="","",S27+N(T27)+N(U27)+N(V27)+N(W27)) -> 207 | Y27: Vestiaire Collective | AA27: 424 | AC27: Sold | AE27: 339 | AF27: 288 | AG27: 0 | AH27: =IF(AND(AC27="Sold",AE27<>"",AF27<>""),AE27-AF27,"") -> 51 | AI27: =IF(AND(AC27="Sold",AF27<>"",X27<>""),AF27-N(AG27)-X27,"") -> 81 | AJ27: =IF(AND(AI27<>"",N(AE27)>0),AI27/AE27,"") -> 0.23893805 | AK27: =IF(AND(AI27<>"",N(X27)>0),AI27/X27,"") -> 0.39130435 | AL27: =IF(AND(AC27="Sold",AD27<>"",Z27<>""),AD27-Z27,"") | AM27: =IF(AND(AC27="Sold",N(AA27)>0,AE27<>""),1-AE27/AA27,"") -> 0.2004717 | AN27: =IF(AND(AC27<>"Sold",AC27<>"",Z27<>""),TODAY()-Z27,"") | AO27: Estimated | AP27: Purchase date had day and month swapped in the original sheet; corrected. Per-bag costs in this lot were split in proportion to sale price; judge the lot as a whole. Platform fee recorded as exactly 15% of the sale; to confirm against the payout.
A28: DEMO-026 | B28: Bottega Veneta | C28: Cloth handbag | E28: Olive green | F28: Leather | H28: Satisfactory | K28: Supplier C | L28: Clearance lot | M28: LOT-B | N28: 1897 | O28: 46235 | P28: 43 | Q28: GBP | R28: 1 | S28: =IF(OR(P28="",R28=""),"",P28*R28) -> 43 | T28: 8 | U28: 4 | V28: 0 | W28: 0 | X28: =IF(S28="","",S28+N(T28)+N(U28)+N(V28)+N(W28)) -> 55 | Y28: Trade buyer (wholesale) | AA28: 93 | AC28: Sold | AE28: 74 | AF28: 74 | AG28: 0 | AH28: =IF(AND(AC28="Sold",AE28<>"",AF28<>""),AE28-AF28,"") -> 0 | AI28: =IF(AND(AC28="Sold",AF28<>"",X28<>""),AF28-N(AG28)-X28,"") -> 19 | AJ28: =IF(AND(AI28<>"",N(AE28)>0),AI28/AE28,"") -> 0.25675676 | AK28: =IF(AND(AI28<>"",N(X28)>0),AI28/X28,"") -> 0.34545455 | AL28: =IF(AND(AC28="Sold",AD28<>"",Z28<>""),AD28-Z28,"") | AM28: =IF(AND(AC28="Sold",N(AA28)>0,AE28<>""),1-AE28/AA28,"") -> 0.20430108 | AN28: =IF(AND(AC28<>"Sold",AC28<>"",Z28<>""),TODAY()-Z28,"") | AO28: Exact | AP28: Purchase date had day and month swapped in the original sheet; corrected. Per-bag costs in this lot were split in proportion to sale price; judge the lot as a whole. Sold to a trade buyer.
A29: DEMO-027 | B29: Loewe | C29: Crossbody | E29: Beige | F29: Canvas / leather | H29: Fair | K29: Supplier C | L29: Clearance lot | M29: LOT-B | N29: 1896 | O29: 46235 | P29: 35 | Q29: GBP | R29: 1 | S29: =IF(OR(P29="",R29=""),"",P29*R29) -> 35 | T29: 8 | U29: 4 | V29: 0 | W29: 0 | X29: =IF(S29="","",S29+N(T29)+N(U29)+N(V29)+N(W29)) -> 47 | Y29: Trade buyer (wholesale) | AA29: 76 | AC29: Sold | AE29: 60 | AF29: 60 | AG29: 0 | AH29: =IF(AND(AC29="Sold",AE29<>"",AF29<>""),AE29-AF29,"") -> 0 | AI29: =IF(AND(AC29="Sold",AF29<>"",X29<>""),AF29-N(AG29)-X29,"") -> 13 | AJ29: =IF(AND(AI29<>"",N(AE29)>0),AI29/AE29,"") -> 0.21666667 | AK29: =IF(AND(AI29<>"",N(X29)>0),AI29/X29,"") -> 0.27659574 | AL29: =IF(AND(AC29="Sold",AD29<>"",Z29<>""),AD29-Z29,"") | AM29: =IF(AND(AC29="Sold",N(AA29)>0,AE29<>""),1-AE29/AA29,"") -> 0.21052632 | AN29: =IF(AND(AC29<>"Sold",AC29<>"",Z29<>""),TODAY()-Z29,"") | AO29: Exact | AP29: Purchase date had day and month swapped in the original sheet; corrected. Per-bag costs in this lot were split in proportion to sale price; judge the lot as a whole. Sold to a trade buyer.
... A49: DEMO-047 | B49: Coach | C49: Vintage leather | E49: Silver | F49: Leather | H49: Fair | K49: Supplier C | L49: Clearance lot | M49: LOT-C | N49: 2336 | O49: 46266 | P49: 43 | Q49: GBP | R49: 1 | S49: =IF(OR(P49="",R49=""),"",P49*R49) -> 43 | T49: 11 | U49: 4 | V49: 0 | W49: 0 | X49: =IF(S49="","",S49+N(T49)+N(U49)+N(V49)+N(W49)) -> 58 | Y49: Trade buyer (wholesale) | AA49: 113 | AC49: Sold | AE49: 82 | AF49: 82 | AG49: 0 | AH49: =IF(AND(AC49="Sold",AE49<>"",AF49<>""),AE49-AF49,"") -> 0 | AI49: =IF(AND(AC49="Sold",AF49<>"",X49<>""),AF49-N(AG49)-X49,"") -> 24 | AJ49: =IF(AND(AI49<>"",N(AE49)>0),AI49/AE49,"") -> 0.29268293 | AK49: =IF(AND(AI49<>"",N(X49)>0),AI49/X49,"") -> 0.4137931 | AL49: =IF(AND(AC49="Sold",AD49<>"",Z49<>""),AD49-Z49,"") | AM49: =IF(AND(AC49="Sold",N(AA49)>0,AE49<>""),1-AE49/AA49,"") -> 0.27433628 | AN49: =IF(AND(AC49<>"Sold",AC49<>"",Z49<>""),TODAY()-Z49,"") | AO49: Exact | AP49: Purchase date had day and month swapped in the original sheet; corrected. Sold to a trade buyer.
A50: DEMO-048 | B50: Ferragamo | C50: Gancini shoulder | E50: Camel | F50: Suede | H50: Satisfactory | K50: Supplier C | L50: Clearance lot | M50: LOT-C | N50: 2032 | O50: 46266 | P50: 56 | Q50: GBP | R50: 1 | S50: =IF(OR(P50="",R50=""),"",P50*R50) -> 56 | T50: 9 | U50: 4 | V50: 0 | W50: 0 | X50: =IF(S50="","",S50+N(T50)+N(U50)+N(V50)+N(W50)) -> 69 | Y50: Trade buyer (wholesale) | AA50: 174 | AC50: In stock, not listed | AH50: =IF(AND(AC50="Sold",AE50<>"",AF50<>""),AE50-AF50,"") | AI50: =IF(AND(AC50="Sold",AF50<>"",X50<>""),AF50-N(AG50)-X50,"") | AJ50: =IF(AND(AI50<>"",N(AE50)>0),AI50/AE50,"") | AK50: =IF(AND(AI50<>"",N(X50)>0),AI50/X50,"") | AL50: =IF(AND(AC50="Sold",AD50<>"",Z50<>""),AD50-Z50,"") | AM50: =IF(AND(AC50="Sold",N(AA50)>0,AE50<>""),1-AE50/AA50,"") | AN50: =IF(AND(AC50<>"Sold",AC50<>"",Z50<>""),TODAY()-Z50,"") | AO50: Exact | AP50: Purchase date had day and month swapped in the original sheet; corrected. Sold to a trade buyer. Not sold yet; still in stock.
A51: DEMO-049 | B51: Marc Jacobs | C51: Stam | E51: Grey | F51: Leather | H51: Satisfactory | K51: Supplier C | L51: Clearance lot | M51: LOT-C | N51: 2028 | O51: 46266 | P51: 47 | Q51: GBP | R51: 1 | S51: =IF(OR(P51="",R51=""),"",P51*R51) -> 47 | T51: 9 | U51: 4 | V51: 0 | W51: 0 | X51: =IF(S51="","",S51+N(T51)+N(U51)+N(V51)+N(W51)) -> 60 | Y51: Trade buyer (wholesale) | AA51: 130 | AC51: In stock, not listed | AH51: =IF(AND(AC51="Sold",AE51<>"",AF51<>""),AE51-AF51,"") | AI51: =IF(AND(AC51="Sold",AF51<>"",X51<>""),AF51-N(AG51)-X51,"") | AJ51: =IF(AND(AI51<>"",N(AE51)>0),AI51/AE51,"") | AK51: =IF(AND(AI51<>"",N(X51)>0),AI51/X51,"") | AL51: =IF(AND(AC51="Sold",AD51<>"",Z51<>""),AD51-Z51,"") | AM51: =IF(AND(AC51="Sold",N(AA51)>0,AE51<>""),1-AE51/AA51,"") | AN51: =IF(AND(AC51<>"Sold",AC51<>"",Z51<>""),TODAY()-Z51,"") | AO51: Exact | AP51: Purchase date had day and month swapped in the original sheet; corrected. Sold to a trade buyer. Not sold yet; still in stock.
A52: DEMO-050 | B52: Burberry | C52: Check tote | E52: Wine | F52: Leather | H52: Good | K52: Supplier C | L52: Clearance lot | M52: LOT-C | N52: 2399 | O52: 46266 | P52: 66 | Q52: GBP | R52: 1 | S52: =IF(OR(P52="",R52=""),"",P52*R52) -> 66 | T52: 11 | U52: 4 | V52: 0 | W52: 0 | X52: =IF(S52="","",S52+N(T52)+N(U52)+N(V52)+N(W52)) -> 81 | Y52: Trade buyer (wholesale) | AA52: 166 | AC52: In stock, not listed | AH52: =IF(AND(AC52="Sold",AE52<>"",AF52<>""),AE52-AF52,"") | AI52: =IF(AND(AC52="Sold",AF52<>"",X52<>""),AF52-N(AG52)-X52,"") | AJ52: =IF(AND(AI52<>"",N(AE52)>0),AI52/AE52,"") | AK52: =IF(AND(AI52<>"",N(X52)>0),AI52/X52,"") | AL52: =IF(AND(AC52="Sold",AD52<>"",Z52<>""),AD52-Z52,"") | AM52: =IF(AND(AC52="Sold",N(AA52)>0,AE52<>""),1-AE52/AA52,"") | AN52: =IF(AND(AC52<>"Sold",AC52<>"",Z52<>""),TODAY()-Z52,"") | AO52: Exact | AP52: Purchase date had day and month swapped in the original sheet; corrected. Sold to a trade buyer. Not sold yet; still in stock.
A53: DEMO-051 | B53: Prada | C53: Denim vintage bag | E53: Denim | F53: Denim | H53: Satisfactory | K53: Supplier D | L53: Collab / partner | M53: COLLAB-A | N53: 411 | P53: 34 | Q53: GBP | R53: 1 | S53: =IF(OR(P53="",R53=""),"",P53*R53) -> 34 | T53: 5 | U53: 0 | V53: 0 | W53: 0 | X53: =IF(S53="","",S53+N(T53)+N(U53)+N(V53)+N(W53)) -> 39 | Y53: Vinted | AA53: 149 | AC53: Sold | AE53: 149 | AF53: 149 | AG53: 0 | AH53: =IF(AND(AC53="Sold",AE53<>"",AF53<>""),AE53-AF53,"") -> 0 | AI53: =IF(AND(AC53="Sold",AF53<>"",X53<>""),AF53-N(AG53)-X53,"") -> 110 | AJ53: =IF(AND(AI53<>"",N(AE53)>0),AI53/AE53,"") -> 0.73825503 | AK53: =IF(AND(AI53<>"",N(X53)>0),AI53/X53,"") -> 2.8205128 | AL53: =IF(AND(AC53="Sold",AD53<>"",Z53<>""),AD53-Z53,"") | AM53: =IF(AND(AC53="Sold",N(AA53)>0,AE53<>""),1-AE53/AA53,"") -> 0 | AN53: =IF(AND(AC53<>"Sold",AC53<>"",Z53<>""),TODAY()-Z53,"") | AO53: Estimated | AP53: Sourced through a Vinted collab arrangement; terms to confirm.
A54: DEMO-052 | B54: Chloé | C54: Faye leather clutch bag | F54: Leather | H54: Satisfactory | K54: Supplier D | L54: Collab / partner | M54: COLLAB-A | N54: 336 | P54: 28 | Q54: GBP | R54: 1 | S54: =IF(OR(P54="",R54=""),"",P54*R54) -> 28 | T54: 4 | U54: 0 | V54: 0 | W54: 0 | X54: =IF(S54="","",S54+N(T54)+N(U54)+N(V54)+N(W54)) -> 32 | Y54: Vinted | AA54: 54 | AC54: Sold | AE54: 54 | AF54: 54 | AG54: 0 | AH54: =IF(AND(AC54="Sold",AE54<>"",AF54<>""),AE54-AF54,"") -> 0 | AI54: =IF(AND(AC54="Sold",AF54<>"",X54<>""),AF54-N(AG54)-X54,"") -> 22 | AJ54: =IF(AND(AI54<>"",N(AE54)>0),AI54/AE54,"") -> 0.40740741 | AK54: =IF(AND(AI54<>"",N(X54)>0),AI54/X54,"") -> 0.6875 | AL54: =IF(AND(AC54="Sold",AD54<>"",Z54<>""),AD54-Z54,"") | AM54: =IF(AND(AC54="Sold",N(AA54)>0,AE54<>""),1-AE54/AA54,"") -> 0 | AN54: =IF(AND(AC54<>"Sold",AC54<>"",Z54<>""),TODAY()-Z54,"") | AO54: Estimated | AP54: Sourced through a Vinted collab arrangement; terms to confirm.
A55: DEMO-053 | B55: Loewe | C55: Amazona Calfskin Tales of Spain Barroco | F55: Calfskin leather | H55: Satisfactory | K55: Supplier D | L55: Collab / partner | M55: COLLAB-A | N55: 398 | P55: 33 | Q55: GBP | R55: 1 | S55: =IF(OR(P55="",R55=""),"",P55*R55) -> 33 | T55: 4 | U55: 0 | V55: 0 | W55: 0 | X55: =IF(S55="","",S55+N(T55)+N(U55)+N(V55)+N(W55)) -> 37 | Y55: Vinted | AA55: 111 | AC55: Sold | AE55: 111 | AF55: 111 | AG55: 0 | AH55: =IF(AND(AC55="Sold",AE55<>"",AF55<>""),AE55-AF55,"") -> 0 | AI55: =IF(AND(AC55="Sold",AF55<>"",X55<>""),AF55-N(AG55)-X55,"") -> 74 | AJ55: =IF(AND(AI55<>"",N(AE55)>0),AI55/AE55,"") -> 0.66666667 | AK55: =IF(AND(AI55<>"",N(X55)>0),AI55/X55,"") -> 2 | AL55: =IF(AND(AC55="Sold",AD55<>"",Z55<>""),AD55-Z55,"") | AM55: =IF(AND(AC55="Sold",N(AA55)>0,AE55<>""),1-AE55/AA55,"") -> 0 | AN55: =IF(AND(AC55<>"Sold",AC55<>"",Z55<>""),TODAY()-Z55,"") | AO55: Estimated | AP55: Sourced through a Vinted collab arrangement; terms to confirm.
A56: DEMO-054 | B56: Prada | C56: Nylon burgundy tote bag | E56: Burgundy | F56: Nylon | H56: Satisfactory | K56: Supplier D | L56: Collab / partner | M56: COLLAB-A | N56: 388 | P56: 32 | Q56: GBP | R56: 1 | S56: =IF(OR(P56="",R56=""),"",P56*R56) -> 32 | T56: 4 | U56: 0 | V56: 0 | W56: 0 | X56: =IF(S56="","",S56+N(T56)+N(U56)+N(V56)+N(W56)) -> 36 | Y56: Vinted | AA56: 54 | AC56: Sold | AE56: 54 | AF56: 54 | AG56: 0 | AH56: =IF(AND(AC56="Sold",AE56<>"",AF56<>""),AE56-AF56,"") -> 0 | AI56: =IF(AND(AC56="Sold",AF56<>"",X56<>""),AF56-N(AG56)-X56,"") -> 18 | AJ56: =IF(AND(AI56<>"",N(AE56)>0),AI56/AE56,"") -> 0.33333333 | AK56: =IF(AND(AI56<>"",N(X56)>0),AI56/X56,"") -> 0.5 | AL56: =IF(AND(AC56="Sold",AD56<>"",Z56<>""),AD56-Z56,"") | AM56: =IF(AND(AC56="Sold",N(AA56)>0,AE56<>""),1-AE56/AA56,"") -> 0 | AN56: =IF(AND(AC56<>"Sold",AC56<>"",Z56<>""),TODAY()-Z56,"") | AO56: Estimated | AP56: Sourced through a Vinted collab arrangement; terms to confirm.
A57: DEMO-055 | B57: Loewe | C57: Vintage bag in mustard | E57: Mustard | H57: Satisfactory | K57: Supplier D | L57: Collab / partner | M57: COLLAB-A | N57: 345 | P57: 29 | Q57: GBP | R57: 1 | S57: =IF(OR(P57="",R57=""),"",P57*R57) -> 29 | T57: 4 | U57: 0 | V57: 0 | W57: 0 | X57: =IF(S57="","",S57+N(T57)+N(U57)+N(V57)+N(W57)) -> 33 | Y57: Vinted | AA57: 69 | AC57: Sold | AE57: 69 | AF57: 69 | AG57: 0 | AH57: =IF(AND(AC57="Sold",AE57<>"",AF57<>""),AE57-AF57,"") -> 0 | AI57: =IF(AND(AC57="Sold",AF57<>"",X57<>""),AF57-N(AG57)-X57,"") -> 36 | AJ57: =IF(AND(AI57<>"",N(AE57)>0),AI57/AE57,"") -> 0.52173913 | AK57: =IF(AND(AI57<>"",N(X57)>0),AI57/X57,"") -> 1.0909091 | AL57: =IF(AND(AC57="Sold",AD57<>"",Z57<>""),AD57-Z57,"") | AM57: =IF(AND(AC57="Sold",N(AA57)>0,AE57<>""),1-AE57/AA57,"") -> 0 | AN57: =IF(AND(AC57<>"Sold",AC57<>"",Z57<>""),TODAY()-Z57,"") | AO57: Estimated | AP57: Sourced through a Vinted collab arrangement; terms to confirm.
A58: DEMO-056 | B58: Loewe | C58: Velazquez leather shoulder bag | F58: Leather | H58: Satisfactory | K58: Supplier D | L58: Collab / partner | M58: COLLAB-A | N58: 353 | P58: 29 | Q58: GBP | R58: 1 | S58: =IF(OR(P58="",R58=""),"",P58*R58) -> 29 | T58: 4 | U58: 0 | V58: 0 | W58: 0 | X58: =IF(S58="","",S58+N(T58)+N(U58)+N(V58)+N(W58)) -> 33 | Y58: Vinted | AA58: 147 | AC58: Sold | AE58: 147 | AF58: 147 | AG58: 0 | AH58: =IF(AND(AC58="Sold",AE58<>"",AF58<>""),AE58-AF58,"") -> 0 | AI58: =IF(AND(AC58="Sold",AF58<>"",X58<>""),AF58-N(AG58)-X58,"") -> 114 | AJ58: =IF(AND(AI58<>"",N(AE58)>0),AI58/AE58,"") -> 0.7755102 | AK58: =IF(AND(AI58<>"",N(X58)>0),AI58/X58,"") -> 3.4545455 | AL58: =IF(AND(AC58="Sold",AD58<>"",Z58<>""),AD58-Z58,"") | AM58: =IF(AND(AC58="Sold",N(AA58)>0,AE58<>""),1-AE58/AA58,"") -> 0 | AN58: =IF(AND(AC58<>"Sold",AC58<>"",Z58<>""),TODAY()-Z58,"") | AO58: Estimated | AP58: Sourced through a Vinted collab arrangement; terms to confirm.
A59: DEMO-057 | B59: Bottega Veneta | C59: Leopard Print Vintage Bag | E59: Leopard print | H59: Satisfactory | K59: Supplier D | L59: Collab / partner | M59: COLLAB-A | N59: 364 | P59: 30 | Q59: GBP | R59: 1 | S59: =IF(OR(P59="",R59=""),"",P59*R59) -> 30 | T59: 4 | U59: 0 | V59: 0 | W59: 0 | X59: =IF(S59="","",S59+N(T59)+N(U59)+N(V59)+N(W59)) -> 34 | Y59: Vinted | AA59: 51 | AC59: Sold | AE59: 51 | AF59: 51 | AG59: 0 | AH59: =IF(AND(AC59="Sold",AE59<>"",AF59<>""),AE59-AF59,"") -> 0 | AI59: =IF(AND(AC59="Sold",AF59<>"",X59<>""),AF59-N(AG59)-X59,"") -> 17 | AJ59: =IF(AND(AI59<>"",N(AE59)>0),AI59/AE59,"") -> 0.33333333 | AK59: =IF(AND(AI59<>"",N(X59)>0),AI59/X59,"") -> 0.5 | AL59: =IF(AND(AC59="Sold",AD59<>"",Z59<>""),AD59-Z59,"") | AM59: =IF(AND(AC59="Sold",N(AA59)>0,AE59<>""),1-AE59/AA59,"") -> 0 | AN59: =IF(AND(AC59<>"Sold",AC59<>"",Z59<>""),TODAY()-Z59,"") | AO59: Estimated | AP59: Sourced through a Vinted collab arrangement; terms to confirm.
...

Sheet Summary
A1: Business summary
A2: Everything here is calculated from the Bags tab. Don't type in this sheet.
A4: Bags tracked | B4: =COUNTA(Bags!$B$3:$B$503) -> 62
A5: Bags sold | B5: =COUNTIF(Bags!$AC$3:$AC$503,"Sold") -> 58
A6: Sell-through % | B6: =IFERROR(B5/B4,0) -> 0.93548387
A7: Revenue from sold bags (£) | B7: =SUMIFS(Bags!$AE$3:$AE$503,Bags!$AC$3:$AC$503,"Sold") -> 11173
A8: Total profit (£) | B8: =SUM(Bags!$AI$3:$AI$503) -> 4922
A9: Overall margin % | B9: =IFERROR(B8/B7,0) -> 0.44052627
A10: Average days to sell | B10: =IFERROR(AVERAGE(Bags!$AL$3:$AL$503),0) -> 0
A11: Unsold stock at cost (£) | B11: =SUMIFS(Bags!$X$3:$X$503,Bags!$AC$3:$AC$503,"<>Sold") -> 255
A12: Rows with estimated or unknown data | B12: =COUNTIF(Bags!$AO$3:$AO$503,"Estimated")+COUNTIF(Bags!$AO$3:$AO$503,"Unknown") -> 32
A15: By sourcing type
A16: Sourcing type | B16: Bags tracked | C16: Sold | D16: Sell-through % | E16: Revenue (£) | F16: Profit (£) | G16: Margin % | H16: Avg days to sell | I16: Avg discount vs list % | J16: Unsold stock at cost (£)
A17: Clearance lot | B17: =COUNTIF(Bags!$L$3:$L$503,$A17) -> 49 | C17: =COUNTIFS(Bags!$L$3:$L$503,$A17,Bags!$AC$3:$AC$503,"Sold") -> 45 | D17: =IFERROR(C17/B17,0) -> 0.91836735 | E17: =SUMIFS(Bags!$AE$3:$AE$503,Bags!$L$3:$L$503,$A17,Bags!$AC$3:$AC$503,"Sold") -> 9516 | F17: =SUMIFS(Bags!$AI$3:$AI$503,Bags!$L$3:$L$503,$A17) -> 4091 | G17: =IFERROR(F17/E17,0) -> 0.42990752 | H17: =IFERROR(AVERAGEIFS(Bags!$AL$3:$AL$503,Bags!$L$3:$L$503,$A17,Bags!$AC$3:$AC$503,"Sold"),0) -> 0 | I17: =IFERROR(AVERAGEIFS(Bags!$AM$3:$AM$503,Bags!$L$3:$L$503,$A17,Bags!$AC$3:$AC$503,"Sold"),0) -> 0.13482385 | J17: =SUMIFS(Bags!$X$3:$X$503,Bags!$L$3:$L$503,$A17,Bags!$AC$3:$AC$503,"<>Sold") -> 255
A18: Selected single | B18: =COUNTIF(Bags!$L$3:$L$503,$A18) -> 1 | C18: =COUNTIFS(Bags!$L$3:$L$503,$A18,Bags!$AC$3:$AC$503,"Sold") -> 1 | D18: =IFERROR(C18/B18,0) -> 1 | E18: =SUMIFS(Bags!$AE$3:$AE$503,Bags!$L$3:$L$503,$A18,Bags!$AC$3:$AC$503,"Sold") -> 614 | F18: =SUMIFS(Bags!$AI$3:$AI$503,Bags!$L$3:$L$503,$A18) -> 204 | G18: =IFERROR(F18/E18,0) -> 0.33224756 | H18: =IFERROR(AVERAGEIFS(Bags!$AL$3:$AL$503,Bags!$L$3:$L$503,$A18,Bags!$AC$3:$AC$503,"Sold"),0) -> 0 | I18: =IFERROR(AVERAGEIFS(Bags!$AM$3:$AM$503,Bags!$L$3:$L$503,$A18,Bags!$AC$3:$AC$503,"Sold"),0) -> 0.50040683 | J18: =SUMIFS(Bags!$X$3:$X$503,Bags!$L$3:$L$503,$A18,Bags!$AC$3:$AC$503,"<>Sold") -> 0
A19: Collab / partner | B19: =COUNTIF(Bags!$L$3:$L$503,$A19) -> 12 | C19: =COUNTIFS(Bags!$L$3:$L$503,$A19,Bags!$AC$3:$AC$503,"Sold") -> 12 | D19: =IFERROR(C19/B19,0) -> 1 | E19: =SUMIFS(Bags!$AE$3:$AE$503,Bags!$L$3:$L$503,$A19,Bags!$AC$3:$AC$503,"Sold") -> 1043 | F19: =SUMIFS(Bags!$AI$3:$AI$503,Bags!$L$3:$L$503,$A19) -> 627 | G19: =IFERROR(F19/E19,0) -> 0.60115053 | H19: =IFERROR(AVERAGEIFS(Bags!$AL$3:$AL$503,Bags!$L$3:$L$503,$A19,Bags!$AC$3:$AC$503,"Sold"),0) -> 0 | I19: =IFERROR(AVERAGEIFS(Bags!$AM$3:$AM$503,Bags!$L$3:$L$503,$A19,Bags!$AC$3:$AC$503,"Sold"),0) -> 0 | J19: =SUMIFS(Bags!$X$3:$X$503,Bags!$L$3:$L$503,$A19,Bags!$AC$3:$AC$503,"<>Sold") -> 0
A22: By brand
A23: Brand | B23: Bags tracked | C23: Sold | D23: Sell-through % | E23: Revenue (£) | F23: Profit (£) | G23: Margin % | H23: Avg days to sell | I23: Avg discount vs list % | J23: Unsold stock at cost (£)
A24: Chanel | B24: =COUNTIF(Bags!$B$3:$B$503,$A24) -> 3 | C24: =COUNTIFS(Bags!$B$3:$B$503,$A24,Bags!$AC$3:$AC$503,"Sold") -> 3 | D24: =IFERROR(C24/B24,0) -> 1 | E24: =SUMIFS(Bags!$AE$3:$AE$503,Bags!$B$3:$B$503,$A24,Bags!$AC$3:$AC$503,"Sold") -> 535 | F24: =SUMIFS(Bags!$AI$3:$AI$503,Bags!$B$3:$B$503,$A24) -> 393 | G24: =IFERROR(F24/E24,0) -> 0.73457944 | H24: =IFERROR(AVERAGEIFS(Bags!$AL$3:$AL$503,Bags!$B$3:$B$503,$A24,Bags!$AC$3:$AC$503,"Sold"),0) -> 0 | I24: =IFERROR(AVERAGEIFS(Bags!$AM$3:$AM$503,Bags!$B$3:$B$503,$A24,Bags!$AC$3:$AC$503,"Sold"),0) -> 0.27616179 | J24: =SUMIFS(Bags!$X$3:$X$503,Bags!$B$3:$B$503,$A24,Bags!$AC$3:$AC$503,"<>Sold") -> 0
A25: Louis Vuitton | B25: =COUNTIF(Bags!$B$3:$B$503,$A25) -> 3 | C25: =COUNTIFS(Bags!$B$3:$B$503,$A25,Bags!$AC$3:$AC$503,"Sold") -> 3 | D25: =IFERROR(C25/B25,0) -> 1 | E25: =SUMIFS(Bags!$AE$3:$AE$503,Bags!$B$3:$B$503,$A25,Bags!$AC$3:$AC$503,"Sold") -> 411 | F25: =SUMIFS(Bags!$AI$3:$AI$503,Bags!$B$3:$B$503,$A25) -> 331 | G25: =IFERROR(F25/E25,0) -> 0.8053528 | H25: =IFERROR(AVERAGEIFS(Bags!$AL$3:$AL$503,Bags!$B$3:$B$503,$A25,Bags!$AC$3:$AC$503,"Sold"),0) -> 0 | I25: =IFERROR(AVERAGEIFS(Bags!$AM$3:$AM$503,Bags!$B$3:$B$503,$A25,Bags!$AC$3:$AC$503,"Sold"),0) -> -0.38701623 | J25: =SUMIFS(Bags!$X$3:$X$503,Bags!$B$3:$B$503,$A25,Bags!$AC$3:$AC$503,"<>Sold") -> 0
A26: Hermès | B26: =COUNTIF(Bags!$B$3:$B$503,$A26) -> 0 | C26: =COUNTIFS(Bags!$B$3:$B$503,$A26,Bags!$AC$3:$AC$503,"Sold") -> 0 | D26: =IFERROR(C26/B26,0) -> 0 | E26: =SUMIFS(Bags!$AE$3:$AE$503,Bags!$B$3:$B$503,$A26,Bags!$AC$3:$AC$503,"Sold") -> 0 | F26: =SUMIFS(Bags!$AI$3:$AI$503,Bags!$B$3:$B$503,$A26) -> 0 | G26: =IFERROR(F26/E26,0) -> 0 | H26: =IFERROR(AVERAGEIFS(Bags!$AL$3:$AL$503,Bags!$B$3:$B$503,$A26,Bags!$AC$3:$AC$503,"Sold"),0) -> 0 | I26: =IFERROR(AVERAGEIFS(Bags!$AM$3:$AM$503,Bags!$B$3:$B$503,$A26,Bags!$AC$3:$AC$503,"Sold"),0) -> 0 | J26: =SUMIFS(Bags!$X$3:$X$503,Bags!$B$3:$B$503,$A26,Bags!$AC$3:$AC$503,"<>Sold") -> 0
A27: Dior | B27: =COUNTIF(Bags!$B$3:$B$503,$A27) -> 5 | C27: =COUNTIFS(Bags!$B$3:$B$503,$A27,Bags!$AC$3:$AC$503,"Sold") -> 5 | D27: =IFERROR(C27/B27,0) -> 1 | E27: =SUMIFS(Bags!$AE$3:$AE$503,Bags!$B$3:$B$503,$A27,Bags!$AC$3:$AC$503,"Sold") -> 2225 | F27: =SUMIFS(Bags!$AI$3:$AI$503,Bags!$B$3:$B$503,$A27) -> 775 | G27: =IFERROR(F27/E27,0) -> 0.34831461 | H27: =IFERROR(AVERAGEIFS(Bags!$AL$3:$AL$503,Bags!$B$3:$B$503,$A27,Bags!$AC$3:$AC$503,"Sold"),0) -> 0 | I27: =IFERROR(AVERAGEIFS(Bags!$AM$3:$AM$503,Bags!$B$3:$B$503,$A27,Bags!$AC$3:$AC$503,"Sold"),0) -> 0.27717223 | J27: =SUMIFS(Bags!$X$3:$X$503,Bags!$B$3:$B$503,$A27,Bags!$AC$3:$AC$503,"<>Sold") -> 0
A28: Gucci | B28: =COUNTIF(Bags!$B$3:$B$503,$A28) -> 7 | C28: =COUNTIFS(Bags!$B$3:$B$503,$A28,Bags!$AC$3:$AC$503,"Sold") -> 7 | D28: =IFERROR(C28/B28,0) -> 1 | E28: =SUMIFS(Bags!$AE$3:$AE$503,Bags!$B$3:$B$503,$A28,Bags!$AC$3:$AC$503,"Sold") -> 1682 | F28: =SUMIFS(Bags!$AI$3:$AI$503,Bags!$B$3:$B$503,$A28) -> 787 | G28: =IFERROR(F28/E28,0) -> 0.46789536 | H28: =IFERROR(AVERAGEIFS(Bags!$AL$3:$AL$503,Bags!$B$3:$B$503,$A28,Bags!$AC$3:$AC$503,"Sold"),0) -> 0 | I28: =IFERROR(AVERAGEIFS(Bags!$AM$3:$AM$503,Bags!$B$3:$B$503,$A28,Bags!$AC$3:$AC$503,"Sold"),0) -> 0.13216691 | J28: =SUMIFS(Bags!$X$3:$X$503,Bags!$B$3:$B$503,$A28,Bags!$AC$3:$AC$503,"<>Sold") -> 0
A29: Prada | B29: =COUNTIF(Bags!$B$3:$B$503,$A29) -> 4 | C29: =COUNTIFS(Bags!$B$3:$B$503,$A29,Bags!$AC$3:$AC$503,"Sold") -> 4 | D29: =IFERROR(C29/B29,0) -> 1 | E29: =SUMIFS(Bags!$AE$3:$AE$503,Bags!$B$3:$B$503,$A29,Bags!$AC$3:$AC$503,"Sold") -> 450 | F29: =SUMIFS(Bags!$AI$3:$AI$503,Bags!$B$3:$B$503,$A29) -> 223 | G29: =IFERROR(F29/E29,0) -> 0.49555556 | H29: =IFERROR(AVERAGEIFS(Bags!$AL$3:$AL$503,Bags!$B$3:$B$503,$A29,Bags!$AC$3:$AC$503,"Sold"),0) -> 0 | I29: =IFERROR(AVERAGEIFS(Bags!$AM$3:$AM$503,Bags!$B$3:$B$503,$A29,Bags!$AC$3:$AC$503,"Sold"),0) -> 0.14194444 | J29: =SUMIFS(Bags!$X$3:$X$503,Bags!$B$3:$B$503,$A29,Bags!$AC$3:$AC$503,"<>Sold") -> 0
A30: Celine | B30: =COUNTIF(Bags!$B$3:$B$503,$A30) -> 0 | C30: =COUNTIFS(Bags!$B$3:$B$503,$A30,Bags!$AC$3:$AC$503,"Sold") -> 0 | D30: =IFERROR(C30/B30,0) -> 0 | E30: =SUMIFS(Bags!$AE$3:$AE$503,Bags!$B$3:$B$503,$A30,Bags!$AC$3:$AC$503,"Sold") -> 0 | F30: =SUMIFS(Bags!$AI$3:$AI$503,Bags!$B$3:$B$503,$A30) -> 0 | G30: =IFERROR(F30/E30,0) -> 0 | H30: =IFERROR(AVERAGEIFS(Bags!$AL$3:$AL$503,Bags!$B$3:$B$503,$A30,Bags!$AC$3:$AC$503,"Sold"),0) -> 0 | I30: =IFERROR(AVERAGEIFS(Bags!$AM$3:$AM$503,Bags!$B$3:$B$503,$A30,Bags!$AC$3:$AC$503,"Sold"),0) -> 0 | J30: =SUMIFS(Bags!$X$3:$X$503,Bags!$B$3:$B$503,$A30,Bags!$AC$3:$AC$503,"<>Sold") -> 0
A31: Fendi | B31: =COUNTIF(Bags!$B$3:$B$503,$A31) -> 3 | C31: =COUNTIFS(Bags!$B$3:$B$503,$A31,Bags!$AC$3:$AC$503,"Sold") -> 3 | D31: =IFERROR(C31/B31,0) -> 1 | E31: =SUMIFS(Bags!$AE$3:$AE$503,Bags!$B$3:$B$503,$A31,Bags!$AC$3:$AC$503,"Sold") -> 659 | F31: =SUMIFS(Bags!$AI$3:$AI$503,Bags!$B$3:$B$503,$A31) -> 487 | G31: =IFERROR(F31/E31,0) -> 0.73899848 | H31: =IFERROR(AVERAGEIFS(Bags!$AL$3:$AL$503,Bags!$B$3:$B$503,$A31,Bags!$AC$3:$AC$503,"Sold"),0) -> 0 | I31: =IFERROR(AVERAGEIFS(Bags!$AM$3:$AM$503,Bags!$B$3:$B$503,$A31,Bags!$AC$3:$AC$503,"Sold"),0) -> -0.003219544 | J31: =SUMIFS(Bags!$X$3:$X$503,Bags!$B$3:$B$503,$A31,Bags!$AC$3:$AC$503,"<>Sold") -> 0
A32: Bottega Veneta | B32: =COUNTIF(Bags!$B$3:$B$503,$A32) -> 7 | C32: =COUNTIFS(Bags!$B$3:$B$503,$A32,Bags!$AC$3:$AC$503,"Sold") -> 6 | D32: =IFERROR(C32/B32,0) -> 0.85714286 | E32: =SUMIFS(Bags!$AE$3:$AE$503,Bags!$B$3:$B$503,$A32,Bags!$AC$3:$AC$503,"Sold") -> 747 | F32: =SUMIFS(Bags!$AI$3:$AI$503,Bags!$B$3:$B$503,$A32) -> 384 | G32: =IFERROR(F32/E32,0) -> 0.51405622 | H32: =IFERROR(AVERAGEIFS(Bags!$AL$3:$AL$503,Bags!$B$3:$B$503,$A32,Bags!$AC$3:$AC$503,"Sold"),0) -> 0 | I32: =IFERROR(AVERAGEIFS(Bags!$AM$3:$AM$503,Bags!$B$3:$B$503,$A32,Bags!$AC$3:$AC$503,"Sold"),0) -> -0.11845063 | J32: =SUMIFS(Bags!$X$3:$X$503,Bags!$B$3:$B$503,$A32,Bags!$AC$3:$AC$503,"<>Sold") -> 45
A33: Saint Laurent | B33: =COUNTIF(Bags!$B$3:$B$503,$A33) -> 0 | C33: =COUNTIFS(Bags!$B$3:$B$503,$A33,Bags!$AC$3:$AC$503,"Sold") -> 0 | D33: =IFERROR(C33/B33,0) -> 0 | E33: =SUMIFS(Bags!$AE$3:$AE$503,Bags!$B$3:$B$503,$A33,Bags!$AC$3:$AC$503,"Sold") -> 0 | F33: =SUMIFS(Bags!$AI$3:$AI$503,Bags!$B$3:$B$503,$A33) -> 0 | G33: =IFERROR(F33/E33,0) -> 0 | H33: =IFERROR(AVERAGEIFS(Bags!$AL$3:$AL$503,Bags!$B$3:$B$503,$A33,Bags!$AC$3:$AC$503,"Sold"),0) -> 0 | I33: =IFERROR(AVERAGEIFS(Bags!$AM$3:$AM$503,Bags!$B$3:$B$503,$A33,Bags!$AC$3:$AC$503,"Sold"),0) -> 0 | J33: =SUMIFS(Bags!$X$3:$X$503,Bags!$B$3:$B$503,$A33,Bags!$AC$3:$AC$503,"<>Sold") -> 0
A34: Balenciaga | B34: =COUNTIF(Bags!$B$3:$B$503,$A34) -> 1 | C34: =COUNTIFS(Bags!$B$3:$B$503,$A34,Bags!$AC$3:$AC$503,"Sold") -> 1 | D34: =IFERROR(C34/B34,0) -> 1 | E34: =SUMIFS(Bags!$AE$3:$AE$503,Bags!$B$3:$B$503,$A34,Bags!$AC$3:$AC$503,"Sold") -> 455 | F34: =SUMIFS(Bags!$AI$3:$AI$503,Bags!$B$3:$B$503,$A34) -> 151 | G34: =IFERROR(F34/E34,0) -> 0.33186813 | H34: =IFERROR(AVERAGEIFS(Bags!$AL$3:$AL$503,Bags!$B$3:$B$503,$A34,Bags!$AC$3:$AC$503,"Sold"),0) -> 0 | I34: =IFERROR(AVERAGEIFS(Bags!$AM$3:$AM$503,Bags!$B$3:$B$503,$A34,Bags!$AC$3:$AC$503,"Sold"),0) -> 0.28683386 | J34: =SUMIFS(Bags!$X$3:$X$503,Bags!$B$3:$B$503,$A34,Bags!$AC$3:$AC$503,"<>Sold") -> 0
A35: Loewe | B35: =COUNTIF(Bags!$B$3:$B$503,$A35) -> 15 | C35: =COUNTIFS(Bags!$B$3:$B$503,$A35,Bags!$AC$3:$AC$503,"Sold") -> 15 | D35: =IFERROR(C35/B35,0) -> 1 | E35: =SUMIFS(Bags!$AE$3:$AE$503,Bags!$B$3:$B$503,$A35,Bags!$AC$3:$AC$503,"Sold") -> 2375 | F35: =SUMIFS(Bags!$AI$3:$AI$503,Bags!$B$3:$B$503,$A35) -> 839 | G35: =IFERROR(F35/E35,0) -> 0.35326316 | H35: =IFERROR(AVERAGEIFS(Bags!$AL$3:$AL$503,Bags!$B$3:$B$503,$A35,Bags!$AC$3:$AC$503,"Sold"),0) -> 0 | I35: =IFERROR(AVERAGEIFS(Bags!$AM$3:$AM$503,Bags!$B$3:$B$503,$A35,Bags!$AC$3:$AC$503,"Sold"),0) -> 0.13207664 | J35: =SUMIFS(Bags!$X$3:$X$503,Bags!$B$3:$B$503,$A35,Bags!$AC$3:$AC$503,"<>Sold") -> 0
... A45: Other | B45: =COUNTIF(Bags!$B$3:$B$503,$A45) -> 1 | C45: =COUNTIFS(Bags!$B$3:$B$503,$A45,Bags!$AC$3:$AC$503,"Sold") -> 1 | D45: =IFERROR(C45/B45,0) -> 1 | E45: =SUMIFS(Bags!$AE$3:$AE$503,Bags!$B$3:$B$503,$A45,Bags!$AC$3:$AC$503,"Sold") -> 86 | F45: =SUMIFS(Bags!$AI$3:$AI$503,Bags!$B$3:$B$503,$A45) -> 50 | G45: =IFERROR(F45/E45,0) -> 0.58139535 | H45: =IFERROR(AVERAGEIFS(Bags!$AL$3:$AL$503,Bags!$B$3:$B$503,$A45,Bags!$AC$3:$AC$503,"Sold"),0) -> 0 | I45: =IFERROR(AVERAGEIFS(Bags!$AM$3:$AM$503,Bags!$B$3:$B$503,$A45,Bags!$AC$3:$AC$503,"Sold"),0) -> 0 | J45: =SUMIFS(Bags!$X$3:$X$503,Bags!$B$3:$B$503,$A45,Bags!$AC$3:$AC$503,"<>Sold") -> 0
A48: By sales channel
A49: Channel | B49: Bags tracked | C49: Sold | D49: Sell-through % | E49: Revenue (£) | F49: Profit (£) | G49: Margin % | H49: Avg days to sell | I49: Avg discount vs list % | J49: Unsold stock at cost (£)
A50: Vinted | B50: =COUNTIF(Bags!$Y$3:$Y$503,$A50) -> 16 | C50: =COUNTIFS(Bags!$Y$3:$Y$503,$A50,Bags!$AC$3:$AC$503,"Sold") -> 16 | D50: =IFERROR(C50/B50,0) -> 1 | E50: =SUMIFS(Bags!$AE$3:$AE$503,Bags!$Y$3:$Y$503,$A50,Bags!$AC$3:$AC$503,"Sold") -> 1801 | F50: =SUMIFS(Bags!$AI$3:$AI$503,Bags!$Y$3:$Y$503,$A50) -> 1254 | G50: =IFERROR(F50/E50,0) -> 0.69627984 | H50: =IFERROR(AVERAGEIFS(Bags!$AL$3:$AL$503,Bags!$Y$3:$Y$503,$A50,Bags!$AC$3:$AC$503,"Sold"),0) -> 0 | I50: =IFERROR(AVERAGEIFS(Bags!$AM$3:$AM$503,Bags!$Y$3:$Y$503,$A50,Bags!$AC$3:$AC$503,"Sold"),0) -> 0.069168481 | J50: =SUMIFS(Bags!$X$3:$X$503,Bags!$Y$3:$Y$503,$A50,Bags!$AC$3:$AC$503,"<>Sold") -> 0
A51: Vestiaire Collective | B51: =COUNTIF(Bags!$Y$3:$Y$503,$A51) -> 12 | C51: =COUNTIFS(Bags!$Y$3:$Y$503,$A51,Bags!$AC$3:$AC$503,"Sold") -> 12 | D51: =IFERROR(C51/B51,0) -> 1 | E51: =SUMIFS(Bags!$AE$3:$AE$503,Bags!$Y$3:$Y$503,$A51,Bags!$AC$3:$AC$503,"Sold") -> 4006 | F51: =SUMIFS(Bags!$AI$3:$AI$503,Bags!$Y$3:$Y$503,$A51) -> 1177 | G51: =IFERROR(F51/E51,0) -> 0.29380929 | H51: =IFERROR(AVERAGEIFS(Bags!$AL$3:$AL$503,Bags!$Y$3:$Y$503,$A51,Bags!$AC$3:$AC$503,"Sold"),0) -> 0 | I51: =IFERROR(AVERAGEIFS(Bags!$AM$3:$AM$503,Bags!$Y$3:$Y$503,$A51,Bags!$AC$3:$AC$503,"Sold"),0) -> 0.24012646 | J51: =SUMIFS(Bags!$X$3:$X$503,Bags!$Y$3:$Y$503,$A51,Bags!$AC$3:$AC$503,"<>Sold") -> 0
A52: Depop | B52: =COUNTIF(Bags!$Y$3:$Y$503,$A52) -> 7 | C52: =COUNTIFS(Bags!$Y$3:$Y$503,$A52,Bags!$AC$3:$AC$503,"Sold") -> 6 | D52: =IFERROR(C52/B52,0) -> 0.85714286 | E52: =SUMIFS(Bags!$AE$3:$AE$503,Bags!$Y$3:$Y$503,$A52,Bags!$AC$3:$AC$503,"Sold") -> 954 | F52: =SUMIFS(Bags!$AI$3:$AI$503,Bags!$Y$3:$Y$503,$A52) -> 799 | G52: =IFERROR(F52/E52,0) -> 0.83752621 | H52: =IFERROR(AVERAGEIFS(Bags!$AL$3:$AL$503,Bags!$Y$3:$Y$503,$A52,Bags!$AC$3:$AC$503,"Sold"),0) -> 0 | I52: =IFERROR(AVERAGEIFS(Bags!$AM$3:$AM$503,Bags!$Y$3:$Y$503,$A52,Bags!$AC$3:$AC$503,"Sold"),0) -> -0.71607606 | J52: =SUMIFS(Bags!$X$3:$X$503,Bags!$Y$3:$Y$503,$A52,Bags!$AC$3:$AC$503,"<>Sold") -> 45
A53: eBay | B53: =COUNTIF(Bags!$Y$3:$Y$503,$A53) -> 1 | C53: =COUNTIFS(Bags!$Y$3:$Y$503,$A53,Bags!$AC$3:$AC$503,"Sold") -> 1 | D53: =IFERROR(C53/B53,0) -> 1 | E53: =SUMIFS(Bags!$AE$3:$AE$503,Bags!$Y$3:$Y$503,$A53,Bags!$AC$3:$AC$503,"Sold") -> 61 | F53: =SUMIFS(Bags!$AI$3:$AI$503,Bags!$Y$3:$Y$503,$A53) -> 7 | G53: =IFERROR(F53/E53,0) -> 0.1147541 | H53: =IFERROR(AVERAGEIFS(Bags!$AL$3:$AL$503,Bags!$Y$3:$Y$503,$A53,Bags!$AC$3:$AC$503,"Sold"),0) -> 0 | I53: =IFERROR(AVERAGEIFS(Bags!$AM$3:$AM$503,Bags!$Y$3:$Y$503,$A53,Bags!$AC$3:$AC$503,"Sold"),0) -> 0.29885057 | J53: =SUMIFS(Bags!$X$3:$X$503,Bags!$Y$3:$Y$503,$A53,Bags!$AC$3:$AC$503,"<>Sold") -> 0
A54: Shopify | B54: =COUNTIF(Bags!$Y$3:$Y$503,$A54) -> 0 | C54: =COUNTIFS(Bags!$Y$3:$Y$503,$A54,Bags!$AC$3:$AC$503,"Sold") -> 0 | D54: =IFERROR(C54/B54,0) -> 0 | E54: =SUMIFS(Bags!$AE$3:$AE$503,Bags!$Y$3:$Y$503,$A54,Bags!$AC$3:$AC$503,"Sold") -> 0 | F54: =SUMIFS(Bags!$AI$3:$AI$503,Bags!$Y$3:$Y$503,$A54) -> 0 | G54: =IFERROR(F54/E54,0) -> 0 | H54: =IFERROR(AVERAGEIFS(Bags!$AL$3:$AL$503,Bags!$Y$3:$Y$503,$A54,Bags!$AC$3:$AC$503,"Sold"),0) -> 0 | I54: =IFERROR(AVERAGEIFS(Bags!$AM$3:$AM$503,Bags!$Y$3:$Y$503,$A54,Bags!$AC$3:$AC$503,"Sold"),0) -> 0 | J54: =SUMIFS(Bags!$X$3:$X$503,Bags!$Y$3:$Y$503,$A54,Bags!$AC$3:$AC$503,"<>Sold") -> 0
A55: Private / direct | B55: =COUNTIF(Bags!$Y$3:$Y$503,$A55) -> 1 | C55: =COUNTIFS(Bags!$Y$3:$Y$503,$A55,Bags!$AC$3:$AC$503,"Sold") -> 1 | D55: =IFERROR(C55/B55,0) -> 1 | E55: =SUMIFS(Bags!$AE$3:$AE$503,Bags!$Y$3:$Y$503,$A55,Bags!$AC$3:$AC$503,"Sold") -> 336 | F55: =SUMIFS(Bags!$AI$3:$AI$503,Bags!$Y$3:$Y$503,$A55) -> 317 | G55: =IFERROR(F55/E55,0) -> 0.94345238 | H55: =IFERROR(AVERAGEIFS(Bags!$AL$3:$AL$503,Bags!$Y$3:$Y$503,$A55,Bags!$AC$3:$AC$503,"Sold"),0) -> 0 | I55: =IFERROR(AVERAGEIFS(Bags!$AM$3:$AM$503,Bags!$Y$3:$Y$503,$A55,Bags!$AC$3:$AC$503,"Sold"),0) -> 0.62995595 | J55: =SUMIFS(Bags!$X$3:$X$503,Bags!$Y$3:$Y$503,$A55,Bags!$AC$3:$AC$503,"<>Sold") -> 0
A56: Trade buyer (wholesale) | B56: =COUNTIF(Bags!$Y$3:$Y$503,$A56) -> 25 | C56: =COUNTIFS(Bags!$Y$3:$Y$503,$A56,Bags!$AC$3:$AC$503,"Sold") -> 22 | D56: =IFERROR(C56/B56,0) -> 0.88 | E56: =SUMIFS(Bags!$AE$3:$AE$503,Bags!$Y$3:$Y$503,$A56,Bags!$AC$3:$AC$503,"Sold") -> 4015 | F56: =SUMIFS(Bags!$AI$3:$AI$503,Bags!$Y$3:$Y$503,$A56) -> 1368 | G56: =IFERROR(F56/E56,0) -> 0.34072229 | H56: =IFERROR(AVERAGEIFS(Bags!$AL$3:$AL$503,Bags!$Y$3:$Y$503,$A56,Bags!$AC$3:$AC$503,"Sold"),0) -> 0 | I56: =IFERROR(AVERAGEIFS(Bags!$AM$3:$AM$503,Bags!$Y$3:$Y$503,$A56,Bags!$AC$3:$AC$503,"Sold"),0) -> 0.27031441 | J56: =SUMIFS(Bags!$X$3:$X$503,Bags!$Y$3:$Y$503,$A56,Bags!$AC$3:$AC$503,"<>Sold") -> 210
...

Sheet Lists
A1: Brand | B1: Condition | C1: Authentication | D1: Currency | E1: Channel | F1: Status | G1: Confidence | H1: Sourcing type
A2: Chanel | B2: New with tags | C2: Platform authenticated | D2: GBP | E2: Vinted | F2: In stock, not listed | G2: Exact | H2: Clearance lot
A3: Louis Vuitton | B3: Excellent | C3: Third-party certificate | D3: USD | E3: Vestiaire Collective | F3: Listed | G3: Estimated | H3: Selected single
A4: Hermès | B4: Very good | C4: Own check only | D4: EUR | E4: Depop | F4: Sold | G4: Unknown | H4: Collab / partner
A5: Dior | B5: Good | C5: None | D5: JPY | E5: eBay | F5: Returned
A6: Gucci | B6: Satisfactory | D6: CNY | E6: Shopify | F6: Delisted / kept
A7: Prada | B7: Fair | D7: HKD | E7: Private / direct
A8: Celine | D8: Other | E8: Trade buyer (wholesale)
A9: Fendi | E9: Other
A10: Bottega Veneta
A11: Saint Laurent
A12: Balenciaga
A13: Loewe
A14: Miu Miu
A15: Chloé
A16: Givenchy
A17: Ferragamo
A18: Mulberry
A19: Marc Jacobs
A20: Coach
A21: Goyard
... A23: Other
